07/10/2023 05:50:50 PM :: PartTracker :: DEBUG    :: --------------------------------------------------------------
07/10/2023 05:50:50 PM :: PartTracker :: DEBUG    :: Beginning particle tracking for h148-2
07/10/2023 05:50:50 PM :: PartTracker :: DEBUG    :: Getting stored filepaths and haloids
07/10/2023 05:50:50 PM :: PartTracker :: ERROR    :: Uncaught exception
Traceback (most recent call last):
  File "/home/watanabe/watanabe_MAP/SNe-heated_Gas_Flow/particletracking.py", line 259, in <module>
    filepaths, haloids, h1ids = get_stored_filepaths_haloids(sim,z0haloid)
  File "/home/watanabe/watanabe_MAP/SNe-heated_Gas_Flow/base.py", line 120, in get_stored_filepaths_haloids
    with open(f'{rootPath}Justice_League_Code/RamPressure/Data/filepaths_haloids.pickle','rb') as f:
FileNotFoundError: [Errno 2] No such file or directory: '/home/watanabe/watanabe_MAP/Justice_League_Code/RamPressure/Data/filepaths_haloids.pickle'
07/10/2023 05:53:40 PM :: PartTracker :: DEBUG    :: --------------------------------------------------------------
07/10/2023 05:53:40 PM :: PartTracker :: DEBUG    :: Beginning particle tracking for h148-2
07/10/2023 05:53:40 PM :: PartTracker :: DEBUG    :: Getting stored filepaths and haloids
07/10/2023 05:53:40 PM :: PartTracker :: ERROR    :: Uncaught exception
Traceback (most recent call last):
  File "/home/watanabe/watanabe_MAP/SNe-heated_Gas_Flow/particletracking.py", line 259, in <module>
    filepaths, haloids, h1ids = get_stored_filepaths_haloids(sim,z0haloid)
  File "/home/watanabe/watanabe_MAP/SNe-heated_Gas_Flow/base.py", line 120, in get_stored_filepaths_haloids
    with open(f'{rootPath}Justice_League_Code/RamPressure/Data/filepaths_haloids.pickle','rb') as f:
FileNotFoundError: [Errno 2] No such file or directory: '/home/watanabe/watanabe_MAP/Justice_League_Code/RamPressure/Data/filepaths_haloids.pickle'
07/10/2023 05:54:08 PM :: PartTracker :: DEBUG    :: --------------------------------------------------------------
07/10/2023 05:54:08 PM :: PartTracker :: DEBUG    :: Beginning particle tracking for h148-2
07/10/2023 05:54:08 PM :: PartTracker :: DEBUG    :: Getting stored filepaths and haloids
07/10/2023 05:54:08 PM :: PartTracker :: ERROR    :: Uncaught exception
Traceback (most recent call last):
  File "/home/watanabe/watanabe_MAP/SNe-heated_Gas_Flow/particletracking.py", line 259, in <module>
    filepaths, haloids, h1ids = get_stored_filepaths_haloids(sim,z0haloid)
  File "/home/watanabe/watanabe_MAP/SNe-heated_Gas_Flow/base.py", line 120, in get_stored_filepaths_haloids
    with open(f'{rootPath}Justice_League_Code/RamPressure/Data/filepaths_haloids.pickle','rb') as f:
FileNotFoundError: [Errno 2] No such file or directory: '/home/watanabe/watanabe_MAP/Justice_League_Code/RamPressure/Data/filepaths_haloids.pickle'
07/10/2023 05:55:31 PM :: PartTracker :: DEBUG    :: --------------------------------------------------------------
07/10/2023 05:55:31 PM :: PartTracker :: DEBUG    :: Beginning particle tracking for h148-2
07/10/2023 05:55:31 PM :: PartTracker :: DEBUG    :: Getting stored filepaths and haloids
07/10/2023 05:55:31 PM :: PartTracker :: ERROR    :: Uncaught exception
Traceback (most recent call last):
  File "/home/watanabe/watanabe_MAP/SNe-heated_Gas_Flow/particletracking.py", line 259, in <module>
    filepaths, haloids, h1ids = get_stored_filepaths_haloids(sim,z0haloid)
  File "/home/watanabe/watanabe_MAP/SNe-heated_Gas_Flow/base.py", line 120, in get_stored_filepaths_haloids
    with open(f'{rootPath}Justice_League_Code/RamPressure/Data/filepaths_haloids.pickle','rb') as f:
FileNotFoundError: [Errno 2] No such file or directory: '/home/watanabe/watanabe_MAP/Justice_League_Code/RamPressure/Data/filepaths_haloids.pickle'
07/10/2023 06:01:12 PM :: PartTracker :: DEBUG    :: --------------------------------------------------------------
07/10/2023 06:01:12 PM :: PartTracker :: DEBUG    :: Beginning particle tracking for h148-2
07/10/2023 06:01:12 PM :: PartTracker :: DEBUG    :: Getting stored filepaths and haloids
07/10/2023 06:01:12 PM :: PartTracker :: ERROR    :: Uncaught exception
Traceback (most recent call last):
  File "/home/watanabe/watanabe_MAP/SNe-heated_Gas_Flow/particletracking.py", line 259, in <module>
    filepaths, haloids, h1ids = get_stored_filepaths_haloids(sim,z0haloid)
  File "/home/watanabe/watanabe_MAP/SNe-heated_Gas_Flow/base.py", line 120, in get_stored_filepaths_haloids
    with open(f'{rootPath}Justice_League_Code/RamPressure/Data/filepaths_haloids.pickle','rb') as f:
FileNotFoundError: [Errno 2] No such file or directory: '/home/watanabe/watanabe_MAP/Justice_League_Code/RamPressure/Data/filepaths_haloids.pickle'
07/10/2023 06:04:02 PM :: PartTracker :: DEBUG    :: --------------------------------------------------------------
07/10/2023 06:04:02 PM :: PartTracker :: DEBUG    :: Beginning particle tracking for h148-2
07/10/2023 06:04:02 PM :: PartTracker :: DEBUG    :: Getting stored filepaths and haloids
07/10/2023 06:04:02 PM :: PartTracker :: ERROR    :: Uncaught exception
Traceback (most recent call last):
  File "/home/watanabe/watanabe_MAP/SNe-heated_Gas_Flow/particletracking.py", line 259, in <module>
    filepaths, haloids, h1ids = get_stored_filepaths_haloids(sim,z0haloid)
  File "/home/watanabe/watanabe_MAP/SNe-heated_Gas_Flow/base.py", line 120, in get_stored_filepaths_haloids
    with open(f'{rootPath}Justice_League_Code/RamPressure/Data/filepaths_haloids.pickle','rb') as f:
FileNotFoundError: [Errno 2] No such file or directory: '/home/watanabe/watanabe_MAP/Justice_League_Code/RamPressure/Data/filepaths_haloids.pickle'
07/11/2023 09:02:27 AM :: PartTracker :: DEBUG    :: --------------------------------------------------------------
07/11/2023 09:02:27 AM :: PartTracker :: DEBUG    :: Beginning particle tracking for h148-2
07/11/2023 09:02:27 AM :: PartTracker :: DEBUG    :: Getting stored filepaths and haloids
07/11/2023 09:02:27 AM :: PartTracker :: ERROR    :: Uncaught exception
Traceback (most recent call last):
  File "/home/watanabe/watanabe_MAP/SNe-heated_Gas_Flow/particletracking.py", line 259, in <module>
    filepaths, haloids, h1ids = get_stored_filepaths_haloids(sim,z0haloid)
  File "/home/watanabe/watanabe_MAP/SNe-heated_Gas_Flow/base.py", line 120, in get_stored_filepaths_haloids
    with open(f'{rootPath}Justice_League_Code/RamPressure/Data/filepaths_haloids.pickle','rb') as f:
FileNotFoundError: [Errno 2] No such file or directory: '/home/watanabe/watanabe_MAP/Justice_League_Code/RamPressure/Data/filepaths_haloids.pickle'
07/11/2023 03:09:29 PM :: PartTracker :: DEBUG    :: --------------------------------------------------------------
07/11/2023 03:09:29 PM :: PartTracker :: DEBUG    :: Beginning particle tracking for h148-2
07/11/2023 03:09:29 PM :: PartTracker :: DEBUG    :: Getting stored filepaths and haloids
07/11/2023 03:09:29 PM :: PartTracker :: ERROR    :: Uncaught exception
Traceback (most recent call last):
  File "/home/watanabe/watanabe_MAP/SNe-heated_Gas_Flow/particletracking.py", line 259, in <module>
    filepaths, haloids, h1ids = get_stored_filepaths_haloids(sim,z0haloid)
  File "/home/watanabe/watanabe_MAP/SNe-heated_Gas_Flow/base.py", line 120, in get_stored_filepaths_haloids
    with open(f'{rootPath}Justice_League_Code/RamPressure/Data/filepaths_haloids.pickle','rb') as f:
FileNotFoundError: [Errno 2] No such file or directory: '/home/watanabe/watanabe_MAP/Justice_League_Code/RamPressure/Data/filepaths_haloids.pickle'
07/11/2023 03:16:32 PM :: PartTracker :: DEBUG    :: --------------------------------------------------------------
07/11/2023 03:16:32 PM :: PartTracker :: DEBUG    :: Beginning particle tracking for h148-2
07/11/2023 03:16:32 PM :: PartTracker :: DEBUG    :: Getting stored filepaths and haloids
07/11/2023 03:16:32 PM :: PartTracker :: ERROR    :: Uncaught exception
Traceback (most recent call last):
  File "/home/watanabe/watanabe_MAP/SNe-heated_Gas_Flow/particletracking.py", line 259, in <module>
    filepaths, haloids, h1ids = get_stored_filepaths_haloids(sim,z0haloid)
  File "/home/watanabe/watanabe_MAP/SNe-heated_Gas_Flow/base.py", line 120, in get_stored_filepaths_haloids
    with open(f'{rootPath}Justice_League_Code/RamPressure/Data/filepaths_haloids.pickle','rb') as f:
FileNotFoundError: [Errno 2] No such file or directory: '/home/watanabe/watanabe_MAP/Justice_League_Code/RamPressure/Data/filepaths_haloids.pickle'
07/11/2023 03:19:23 PM :: PartTracker :: DEBUG    :: --------------------------------------------------------------
07/11/2023 03:19:23 PM :: PartTracker :: DEBUG    :: Beginning particle tracking for h148-2
07/11/2023 03:19:23 PM :: PartTracker :: DEBUG    :: Getting stored filepaths and haloids
07/11/2023 03:19:23 PM :: PartTracker :: ERROR    :: Uncaught exception
Traceback (most recent call last):
  File "/home/watanabe/watanabe_MAP/SNe-heated_Gas_Flow/particletracking.py", line 259, in <module>
    filepaths, haloids, h1ids = get_stored_filepaths_haloids(sim,z0haloid)
  File "/home/watanabe/watanabe_MAP/SNe-heated_Gas_Flow/base.py", line 120, in get_stored_filepaths_haloids
    with open(f'{rootPath}Justice_League_Code/RamPressure/Data/filepaths_haloids.pickle','rb') as f:
FileNotFoundError: [Errno 2] No such file or directory: '/home/watanabe/watanabe_MAP/Justice_League_Code/RamPressure/Data/filepaths_haloids.pickle'
07/11/2023 03:25:28 PM :: PartTracker :: DEBUG    :: --------------------------------------------------------------
07/11/2023 03:25:28 PM :: PartTracker :: DEBUG    :: Beginning particle tracking for h148-2
07/11/2023 03:25:28 PM :: PartTracker :: DEBUG    :: Getting stored filepaths and haloids
07/11/2023 03:25:28 PM :: PartTracker :: ERROR    :: Uncaught exception
Traceback (most recent call last):
  File "/home/watanabe/watanabe_MAP/SNe-heated_Gas_Flow/particletracking.py", line 259, in <module>
    filepaths, haloids, h1ids = get_stored_filepaths_haloids(sim,z0haloid)
  File "/home/watanabe/watanabe_MAP/SNe-heated_Gas_Flow/base.py", line 120, in get_stored_filepaths_haloids
    with open(f'{rootPath}Justice_League_Code/RamPressure/Data/timesteps_data/filepaths_haloids.pickle','rb') as f:
FileNotFoundError: [Errno 2] No such file or directory: '/home/watanabe/watanabe_MAP/Justice_League_Code/RamPressure/Data/timesteps_data/filepaths_haloids.pickle'
07/11/2023 03:27:46 PM :: PartTracker :: DEBUG    :: --------------------------------------------------------------
07/11/2023 03:27:46 PM :: PartTracker :: DEBUG    :: Beginning particle tracking for h148-2
07/11/2023 03:27:46 PM :: PartTracker :: DEBUG    :: Getting stored filepaths and haloids
07/11/2023 03:27:46 PM :: PartTracker :: DEBUG    :: Getting starting snapshot (may take a while)
07/11/2023 03:27:50 PM :: PartTracker :: DEBUG    :: Start on snapshot 11, 2944
07/11/2023 03:27:50 PM :: PartTracker :: DEBUG    :: Could not find iords file, computing iords to track
07/11/2023 03:34:30 PM :: PartTracker :: DEBUG    :: Saving iords file to ../Justice_league_Code/Data/iords/h148_2.pickle
07/11/2023 03:34:30 PM :: PartTracker :: ERROR    :: Uncaught exception
Traceback (most recent call last):
  File "/home/watanabe/watanabe_MAP/SNe-heated_Gas_Flow/particletracking.py", line 287, in <module>
    output = run_tracking(sim, z0haloid, filepaths, haloids, h1ids)
  File "/home/watanabe/watanabe_MAP/SNe-heated_Gas_Flow/particletracking.py", line 47, in run_tracking
    iords = get_iords(sim, z0haloid, filepaths, haloids)
  File "/home/watanabe/watanabe_MAP/SNe-heated_Gas_Flow/particletracking.py", line 40, in get_iords
    with open(path,'wb') as outfile:
FileNotFoundError: [Errno 2] No such file or directory: '../Justice_league_Code/Data/iords/h148_2.pickle'
07/12/2023 10:12:35 AM :: PartTracker :: DEBUG    :: --------------------------------------------------------------
07/12/2023 10:12:35 AM :: PartTracker :: DEBUG    :: Beginning particle tracking for h148-2
07/12/2023 10:12:35 AM :: PartTracker :: DEBUG    :: Getting stored filepaths and haloids
07/12/2023 10:12:35 AM :: PartTracker :: DEBUG    :: Getting starting snapshot (may take a while)
07/12/2023 10:12:38 AM :: PartTracker :: DEBUG    :: Start on snapshot 11, 2944
07/12/2023 10:12:38 AM :: PartTracker :: DEBUG    :: Could not find iords file, computing iords to track
07/12/2023 10:19:05 AM :: PartTracker :: DEBUG    :: Saving iords file to ../Justice_league_Code/Data/iords/h148_2.pickle
07/12/2023 10:19:05 AM :: PartTracker :: ERROR    :: Uncaught exception
Traceback (most recent call last):
  File "/home/watanabe/watanabe_MAP/SNe-heated_Gas_Flow/particletracking.py", line 287, in <module>
    output = run_tracking(sim, z0haloid, filepaths, haloids, h1ids)
  File "/home/watanabe/watanabe_MAP/SNe-heated_Gas_Flow/particletracking.py", line 47, in run_tracking
    iords = get_iords(sim, z0haloid, filepaths, haloids)
  File "/home/watanabe/watanabe_MAP/SNe-heated_Gas_Flow/particletracking.py", line 40, in get_iords
    with open(path,'wb') as outfile:
FileNotFoundError: [Errno 2] No such file or directory: '../Justice_league_Code/Data/iords/h148_2.pickle'
07/12/2023 10:25:04 AM :: PartTracker :: DEBUG    :: --------------------------------------------------------------
07/12/2023 10:25:04 AM :: PartTracker :: DEBUG    :: Beginning particle tracking for h148-2
07/12/2023 10:25:04 AM :: PartTracker :: DEBUG    :: Getting stored filepaths and haloids
07/12/2023 10:25:04 AM :: PartTracker :: DEBUG    :: Getting starting snapshot (may take a while)
07/12/2023 10:25:07 AM :: PartTracker :: DEBUG    :: Start on snapshot 11, 2944
07/12/2023 10:25:07 AM :: PartTracker :: DEBUG    :: Found iords file at ../Justice_League_Code/Data/iords/h148_2.pickle, loading these
07/12/2023 10:25:07 AM :: PartTracker :: WARNING  :: If you have recently changed something, these iords might not be correct
07/12/2023 10:25:07 AM :: PartTracker :: DEBUG    :: Starting tracking
07/12/2023 10:25:49 AM :: PartTracker :: DEBUG    :: * Snapshot 2944
07/12/2023 10:31:27 AM :: PartTracker :: DEBUG    :: * Snapshot 3072
07/12/2023 10:37:06 AM :: PartTracker :: DEBUG    :: * Snapshot 3195
07/12/2023 10:42:47 AM :: PartTracker :: DEBUG    :: * Snapshot 3200
07/12/2023 10:48:28 AM :: PartTracker :: DEBUG    :: * Snapshot 3328
07/12/2023 10:54:14 AM :: PartTracker :: DEBUG    :: * Snapshot 3456
07/12/2023 11:00:06 AM :: PartTracker :: DEBUG    :: * Snapshot 3584
07/12/2023 11:05:58 AM :: PartTracker :: DEBUG    :: * Snapshot 3606
07/12/2023 11:11:52 AM :: PartTracker :: DEBUG    :: * Snapshot 3712
07/12/2023 11:17:49 AM :: PartTracker :: DEBUG    :: * Snapshot 3840
07/12/2023 11:23:52 AM :: PartTracker :: DEBUG    :: * Snapshot 3968
07/12/2023 11:29:59 AM :: PartTracker :: DEBUG    :: * Snapshot 4096
07/12/2023 11:35:14 AM :: PartTracker :: DEBUG    :: Saving output to ../../Data/tracked_particles.hdf5
07/12/2023 11:35:14 AM :: PartTracker :: ERROR    :: Uncaught exception
Traceback (most recent call last):
  File "/home/watanabe/watanabe_MAP/SNe-heated_Gas_Flow/particletracking.py", line 291, in <module>
    output.to_hdf(savepath,key=f'{sim}_{z0haloid}')
  File "/home/watanabe/anaconda3/envs/conda-env-py39/lib/python3.9/site-packages/pandas/core/generic.py", line 2799, in to_hdf
    pytables.to_hdf(
  File "/home/watanabe/anaconda3/envs/conda-env-py39/lib/python3.9/site-packages/pandas/io/pytables.py", line 298, in to_hdf
    with HDFStore(
  File "/home/watanabe/anaconda3/envs/conda-env-py39/lib/python3.9/site-packages/pandas/io/pytables.py", line 578, in __init__
    self.open(mode=mode, **kwargs)
  File "/home/watanabe/anaconda3/envs/conda-env-py39/lib/python3.9/site-packages/pandas/io/pytables.py", line 737, in open
    self._handle = tables.open_file(self._path, self._mode, **kwargs)
  File "/home/watanabe/anaconda3/envs/conda-env-py39/lib/python3.9/site-packages/tables/file.py", line 300, in open_file
    return File(filename, mode, title, root_uep, filters, **kwargs)
  File "/home/watanabe/anaconda3/envs/conda-env-py39/lib/python3.9/site-packages/tables/file.py", line 750, in __init__
    self._g_new(filename, mode, **params)
  File "tables/hdf5extension.pyx", line 366, in tables.hdf5extension.File._g_new
  File "/home/watanabe/anaconda3/envs/conda-env-py39/lib/python3.9/site-packages/tables/utils.py", line 169, in check_file_access
    check_file_access(path, 'w')
  File "/home/watanabe/anaconda3/envs/conda-env-py39/lib/python3.9/site-packages/tables/utils.py", line 157, in check_file_access
    raise FileNotFoundError(f"``{path.parent}`` does not exist")
FileNotFoundError: ``/home/watanabe/Data`` does not exist
07/12/2023 11:49:13 AM :: PartTracker :: DEBUG    :: --------------------------------------------------------------
07/12/2023 11:49:13 AM :: PartTracker :: DEBUG    :: Beginning particle tracking for h148-2
07/12/2023 11:49:13 AM :: PartTracker :: DEBUG    :: Getting stored filepaths and haloids
07/12/2023 11:49:13 AM :: PartTracker :: DEBUG    :: Getting starting snapshot (may take a while)
07/12/2023 11:49:15 AM :: PartTracker :: DEBUG    :: Start on snapshot 11, 2944
07/12/2023 11:49:15 AM :: PartTracker :: DEBUG    :: Found iords file at ../Justice_League_Code/Data/iords/h148_2.pickle, loading these
07/12/2023 11:49:15 AM :: PartTracker :: WARNING  :: If you have recently changed something, these iords might not be correct
07/12/2023 11:49:15 AM :: PartTracker :: DEBUG    :: Starting tracking
07/12/2023 11:49:57 AM :: PartTracker :: DEBUG    :: * Snapshot 2944
07/12/2023 11:55:13 AM :: PartTracker :: DEBUG    :: * Snapshot 3072
07/12/2023 12:00:28 PM :: PartTracker :: DEBUG    :: * Snapshot 3195
07/12/2023 12:05:47 PM :: PartTracker :: DEBUG    :: * Snapshot 3200
07/12/2023 12:11:22 PM :: PartTracker :: DEBUG    :: * Snapshot 3328
07/12/2023 12:16:44 PM :: PartTracker :: DEBUG    :: * Snapshot 3456
07/12/2023 12:22:21 PM :: PartTracker :: DEBUG    :: * Snapshot 3584
07/12/2023 12:27:49 PM :: PartTracker :: DEBUG    :: * Snapshot 3606
07/12/2023 12:33:34 PM :: PartTracker :: DEBUG    :: * Snapshot 3712
07/12/2023 12:39:14 PM :: PartTracker :: DEBUG    :: * Snapshot 3840
07/12/2023 12:45:06 PM :: PartTracker :: DEBUG    :: * Snapshot 3968
07/12/2023 12:51:13 PM :: PartTracker :: DEBUG    :: * Snapshot 4096
07/12/2023 12:56:24 PM :: PartTracker :: DEBUG    :: Saving output to ../Justice_League_Code/Data/tracked_particles.hdf5
